<?xml version="1.0" encoding="utf-8"?>
<!-- This URDF was automatically created by SolidWorks to URDF Exporter! Originally created by Stephen Brawner (brawner@gmail.com) 
     Commit Version: 1.6.0-4-g7f85cfe  Build Version: 1.6.7995.38578
     For more information, please see http://wiki.ros.org/sw_urdf_exporter -->
<robot name="xpkg_urdf_saberd6x">
    <link name="base_link">
        <inertial>
            <origin xyz="-0.0027793 -9.439E-06 0.033407" rpy="0 0 0" />
            <mass value="0.2873" />
            <inertia ixx="0.00038435" ixy="-2.1028E-08" ixz="1.6655E-05"
                    iyy="0.00040643" iyz="-9.8042E-10" izz="0.00048639" />
        </inertial>
        <visual>
            <origin xyz="0 0 0" rpy="0 0 0" />
            <geometry>
                <mesh filename="package://xpkg_urdf_saberd6x/urdf/meshes/base_link.STL" />
            </geometry>
            <material name="">
                <color rgba="0.6 0.6 0.6 1" />
            </material>
        </visual>
        <collision>
            <origin xyz="0 0 0" rpy="0 0 0" />
            <geometry>
                <mesh filename="package://xpkg_urdf_saberd6x/urdf/meshes/base_link.STL" />
            </geometry>
        </collision>
    </link>
    
    <link name="link_1">
        <inertial>
            <origin xyz="0.0060334 0.0047366 0.027609" rpy="0 0 0" />
            <mass value="0.22105" />
            <inertia ixx="0.000106" ixy="-3.0677E-07" ixz="-1.5507E-05"
                    iyy="0.0001891" iyz="-9.9365E-08" izz="0.00015759" />
        </inertial>
        <visual>
            <origin xyz="0 0 0" rpy="0 0 0" />
            <geometry>
                <mesh filename="package://xpkg_urdf_saberd6x/urdf/meshes/link_1.STL" />
            </geometry>
            <material name="">
                <color rgba="0.6 0.6 0.6 1" />
            </material>
        </visual>
        <collision>
            <origin xyz="0 0 0" rpy="0 0 0" />
            <geometry>
                <mesh filename="package://xpkg_urdf_saberd6x/urdf/meshes/link_1.STL" />
            </geometry>
        </collision>
    </link>
    <joint name="joint_1" type="revolute">
        <origin xyz="0 0 0.0795" rpy="0 0 0" />
        <parent link="base_link" />
        <child link="link_1" />
        <axis xyz="0 0 1" />
        <limit effort="40.0" lower="-2.9845" upper="2.9845" velocity="100" />
    </joint>

    <link name="link_2">
        <inertial>
            <origin xyz="0.00016024 -0.00026641 0.1639" rpy="0 0 0" />
            <mass value="0.90382" />
            <inertia ixx="0.0056179" ixy="1.9731E-08" ixz="1.1466E-05"
                    iyy="0.0057706" iyz="-8.018E-07" izz="0.00034731" />
        </inertial>
        <visual>
            <origin xyz="0 0 0" rpy="0 0 0" />
            <geometry>
                <mesh filename="package://xpkg_urdf_saberd6x/urdf/meshes/link_2.STL" />
            </geometry>
            <material name="">
                <color rgba="0.6 0.6 0.6 1" />
            </material>
        </visual>
        <collision>
            <origin xyz="0 0 0" rpy="0 0 0" />
            <geometry>
                <mesh filename="package://xpkg_urdf_saberd6x/urdf/meshes/link_2.STL" />
            </geometry>
        </collision>
    </link>
    <joint name="joint_2" type="revolute">
        <origin xyz="0.015 0 0.0385" rpy="0 0 0" />
        <parent link="link_1" />
        <child link="link_2" />
        <axis xyz="0 1 0" />
        <limit effort="40.0" lower="-2.0944" upper="1.5708" velocity="100" />
    </joint>
    
    <link name="link_3">
        <inertial>
            <origin xyz="-0.060758 0.0015314 0.063124" rpy="0 0 0" />
            <mass value="0.77967" />
            <inertia ixx="0.0013164" ixy="6.7544E-07" ixz="0.00036698"
                    iyy="0.0017075" iyz="-1.8109E-06" izz="0.00062047" />
        </inertial>
        <visual>
            <origin xyz="0 0 0" rpy="0 0 0" />
            <geometry>
                <mesh filename="package://xpkg_urdf_saberd6x/urdf/meshes/link_3.STL" />
            </geometry>
            <material name="">
                <color rgba="0.6 0.6 0.6 1" />
            </material>
        </visual>
        <collision>
            <origin xyz="0 0 0" rpy="0 0 0" />
            <geometry>
                <mesh filename="package://xpkg_urdf_saberd6x/urdf/meshes/link_3.STL" />
            </geometry>
        </collision>
    </link>
    <joint name="joint_3" type="revolute">
        <origin xyz="0 0 0.3" rpy="0 0 0" />
        <parent link="link_2" />
        <child link="link_3" />
        <axis xyz="0 1 0" />
        <limit effort="40.0" lower="-0.3927" upper="3.1416" velocity="0" />
    </joint>

    <link name="link_4">
        <inertial>
            <origin xyz="2.0187E-05 -0.0020115 0.041453" rpy="0 0 0" />
            <mass value="0.27032" />
            <inertia ixx="0.00012345" ixy="-3.6634E-08" ixz="7.7235E-09"
                    iyy="0.0001646" iyz="3.282E-07" izz="0.00012046" />
        </inertial>
        <visual>
            <origin xyz="0 0 0" rpy="0 0 0" />
            <geometry>
                <mesh filename="package://xpkg_urdf_saberd6x/urdf/meshes/link_4.STL" />
            </geometry>
            <material name="">
                <color rgba="0.6 0.6 0.6 1" />
            </material>
        </visual>
        <collision>
            <origin xyz="0 0 0" rpy="0 0 0" />
            <geometry>
                <mesh filename="package://xpkg_urdf_saberd6x/urdf/meshes/link_4.STL" />
            </geometry>
        </collision>
    </link>
    <joint name="joint_4" type="revolute">
        <origin xyz="-0.072 0 0.185" rpy="0 0 0" />
        <parent link="link_3" />
        <child link="link_4" />
        <axis xyz="0 0 1" />
        <limit effort="40.0" lower="-2.9670597284" upper="2.9670597284" velocity="0" />
    </joint>

    <link name="link_5">
        <inertial>
            <origin xyz="0.001888 -0.0018108 0.055464" rpy="0 0 0" />
            <mass value="0.26763" />
            <inertia ixx="0.00013501" ixy="-4.1848E-08" ixz="-9.9225E-08"
                    iyy="0.00010699" iyz="-4.0834E-08" izz="8.4868E-05" />
        </inertial>
        <visual>
            <origin xyz="0 0 0" rpy="0 0 0" />
            <geometry>
                <mesh filename="package://xpkg_urdf_saberd6x/urdf/meshes/link_5.STL" />
            </geometry>
            <material name="">
                <color rgba="0.6 0.6 0.6 1" />
            </material>
        </visual>
        <collision>
            <origin xyz="0 0 0" rpy="0 0 0" />
            <geometry>
                <mesh filename="package://xpkg_urdf_saberd6x/urdf/meshes/link_5.STL" />
            </geometry>
        </collision>
    </link>
    <joint name="joint_5" type="revolute">
        <origin xyz="0 0 0.051" rpy="0 0 0" />
        <parent link="link_4" />
        <child link="link_5" />
        <axis xyz="0 1 0" />
        <limit effort="40.0" lower="-1.6580627894" upper="1.6580627894" velocity="100" />
    </joint>

    <link name="link_6">
        <inertial>
            <origin xyz="0.0092374 -7.1267E-11 0.022578" rpy="0 0 0" />
            <mass value="0.024422" />
            <inertia ixx="7.9532E-06" ixy="-3.7581E-15" ixz="5.8837E-08"
                    iyy="5.5751E-06" iyz="3.788E-14" izz="5.766E-06" />
        </inertial>
        <visual>
            <origin xyz="0 0 0" rpy="0 0 0" />
            <geometry>
                <mesh filename="package://xpkg_urdf_saberd6x/urdf/meshes/link_6.STL" />
            </geometry>
            <material name="">
                <color rgba="0.6 0.6 0.6 1" />
            </material>
        </visual>
        <collision>
            <origin xyz="0 0 0" rpy="0 0 0" />
            <geometry>
                <mesh filename="package://xpkg_urdf_saberd6x/urdf/meshes/link_6.STL" />
            </geometry>
        </collision>
    </link>
    <joint name="joint_6" type="revolute">
        <origin xyz="-0.027 0 0.075" rpy="0 0 0" />
        <parent link="link_5" />
        <child link="link_6" />
        <axis xyz="-1 0 0" />
        <limit effort="40.0" lower="-1.6057029118" upper="1.6057029118" velocity="100" />
    </joint>
</robot>
